Workbook

Sheet Start Here
B1: ✨ Social Media Content Planner
B2: Plan once. The calendar, weekly view and dashboard fill themselves.
C4: QUICK START
B6: 1 | C6: Set up your brand → Setup tab
C7: Add your platforms (with handles, monthly post goals and caption/hashtag limits), your content pillars with a target mix, post formats and team members. These power every dropdown and goal in the planner.
B9: 2 | C9: Plan your posts → Content Log tab
C10: One row per post: date, time, platform, format, pillar, hook, caption, hashtag set and status. Delete the sample rows first. ⚠ Flags warn you about overdue posts, captions over the platform limit and too many hashtags.
B12: 3 | C12: See it & improve it → Calendar, Weekly View, Dashboard
C13: The Monthly Calendar and Weekly View build themselves. After posting, add reach, likes, comments, shares, saves and clicks to the log — the Dashboard shows what's working by platform, pillar, format and weekday, plus your top posts.
C15: WHAT'S IN THIS PLANNER
C16: Setup | D16: Platforms, pillars, formats, team, week start
C17: Content Log | D17: The one place you enter posts + results
C18: Monthly Calendar | D18: Auto-filled month grid, status icons, overdue count
C19: Weekly View | D19: Any week at a glance, up to 8 posts/day
C20: Dashboard | D20: KPIs, platform goals, pillar balance, best day, top 5 posts, charts
C21: Growth Tracker | D21: Monthly followers per platform → growth + chart
C22: Ideas Bank | D22: Capture & prioritise ideas
C23: Hashtag Bank | D23: Reusable, counted hashtag sets
C25: COLOUR KEY
C26: Type here | D26: Cream cells are inputs — yours to edit.
C27: Automatic | D27: White cells and grey headers are formulas — leave them be.
C28: Status icons | D28: 💡 Idea ✏️ Drafting 👀 In Review 🕒 Scheduled ✅ Published ♻️ Repurpose
C30: GOOD TO KNOW
C31: • Works in Microsoft Excel and Google Sheets (File ▸ Import ▸ Upload in Sheets).
C32: • Engagement rate = (likes + comments + shares + saves) ÷ reach.
C33: • Need more than 3 posts on a day? The calendar shows '+N more' — open the Weekly View for all of them.
C34: • Room for 500 posts, 10 platforms, 8 pillars, 14 formats. Keep adding rows inside the cream area.
C35: • Sorting the Content Log: select the whole table (incl. headers) and sort by Date.

Sheet Setup
B1: ⚙️ Setup
B2: Everything here feeds the dropdowns, goals and checks across the planner. Cream cells are yours to edit.
B4: Brand / account | C4: Your Brand Co.
B5: Week starts on | C5: Sunday
B8: Platform | C8: Handle | D8: Monthly post goal | E8: Caption limit (chars) | F8: Hashtag limit | G8: Content pillar | H8: What it covers | I8: Target mix | K8: Post format | M8: Status | N8: Icon | P8: Team / owner | R8: Months
B9: Instagram | C9: @yourbrand | D9: 12 | E9: 2200 | F9: 30 | G9: Educate | H9: Tips, how-tos, tutorials, myth-busting | I9: 0.3 | K9: Reel / Short video | M9: Idea | N9: 💡 | P9: Me | R9: January
B10: TikTok | C10: @yourbrand | D10: 12 | E10: 4000 | F10: 10 | G10: Inspire | H10: Results, stories, transformations, quotes | I10: 0.2 | K10: Carousel | M10: Drafting | N10: ✏️ | P10: Designer | R10: February
B11: YouTube | C11: @yourbrand | D11: 4 | E11: 5000 | F11: 15 | G11: Entertain | H11: Trends, humour, behind-the-scenes | I11: 0.2 | K11: Single image | M11: In Review | N11: 👀 | P11: Video editor | R11: March
B12: LinkedIn | C12: /company/yourbrand | D12: 8 | E12: 3000 | F12: 5 | G12: Promote | H12: Offers, launches, product features | I12: 0.15 | K12: Story | M12: Scheduled | N12: 🕒 | P12: VA | R12: April
B13: Facebook | C13: /yourbrand | D13: 8 | E13: 63206 | F13: 10 | G13: Community | H13: UGC, Q&A, polls, shout-outs | I13: 0.15 | K13: Long-form video | M13: Published | N13: ✅ | R13: May
B14: Pinterest | C14: @yourbrand | D14: 10 | E14: 500 | F14: 20 | K14: Live | M14: Repurpose | N14: ♻️ | R14: June
B15: X / Twitter | C15: @yourbrand | D15: 12 | E15: 280 | F15: 3 | K15: Text post | M15: Fixed list — used by formulas | R15: July
B16: Threads | C16: @yourbrand | D16: 8 | E16: 500 | F16: 1 | K16: Thread | R16: August
H17: Total (aim for 100%) | I17: =SUM(I9:I16) -> 1 | K17: Pin | R17: September
K18: Poll | R18: October
K19: Article / Blog | R19: November
K20: Newsletter | R20: December
B21: Tips: add up to 10 platforms, 8 pillars, 14 formats and 8 team members — new entries appear in every dropdown, the Dashboard and the Growth Tracker automatically. Caption & hashtag limits drive the ✂ and # warnings in the Content Log. | R21: Full Year

Sheet Content Log
B1: 📝 Content Log
B2: One row per post. Enter it here once — the Calendar, Weekly View and Dashboard fill themselves. Cream = you type · white = automatic.
A3: PLAN & CREATE | S3: RESULTS (fill in after posting — Eng. rate = engagements ÷ reach) | AC3: Helper columns — automatic, please don't edit
A4: Date | B4: Day | C4: Time | D4: Platform | E4: Format | F4: Pillar | G4: Campaign | H4: Hook / Title | I4: Caption | J4: Chars | K4: Call to action | L4: Hashtag set | M4: # Tags | N4: Asset link | O4: Status | P4: Owner | Q4: ⚠ Flags | R4: Post URL | S4: Impressions | T4: Reach | U4: Likes | V4: Comments | W4: Shares | X4: Saves | Y4: Clicks | Z4: Engagements | AA4: Eng. rate | AB4: Notes | AC4: helper: sort key | AD4: helper: day slot | AE4: helper: calendar label | AF4: helper: top-post score | AG4: helper: weekday
A5: 46287 | B5: =IF(A5="","",TEXT(A5,"ddd")) -> Tue | C5: 0.375 | D5: Instagram | E5: Carousel | F5: Educate | G5: Evergreen | H5: 5 mistakes killing your reach | I5: Swipe → the 5 mistakes we see every week (and the fix for each). | J5: =IF(I5="","",LEN(I5)) -> 64 | K5: Save for later | L5: IG – Growth tips | M5: =IF(L5="","",IFERROR(INDEX('Hashtag Bank'!$E$5:$E$104,MATCH(L5,'Hashtag Bank'!$B$5:$B$104,0)),"")) -> 8 | O5: Published | P5: Me | Q5: =IF(A5&H5="","",TRIM(IF(AND(A5<>"",A5<TODAY(),O5<>"Published",O5<>"Repurpose"),"⚠ Overdue ","")&IF(AND(J5<>"",D5<>"",IFERROR(J5>INDEX(Setup!$E$9:$E$18,MATCH(D5,Setup!$B$9:$B$18,0)),FALSE())),"✂ Caption too long ","")&IF(AND(M5<>"",D5<>"",IFERROR(M5>INDEX(Setup!$F$9:$F$18,MATCH(D5,Setup!$B$9:$B$18,0)),FALSE())),"# Too many tags",""))) | S5: 8420 | T5: 6110 | U5: 512 | V5: 48 | W5: 66 | X5: 301 | Y5: 40 | Z5: =IF(COUNT(U5:X5)=0,"",SUM(U5:X5)) -> 927 | AA5: =IF(OR(Z5="",N(T5)=0),"",Z5/T5) -> 0.15171849 | AB5: SAMPLE ROW — delete sample rows before you start | AC5: =IF(A5="","",A5+N(C5)+ROW()/10^7) -> 46287.375 | AD5: =IF(A5="","",TEXT(A5,"0")&"|"&COUNTIFS('Content Log'!$A$5:$A$504,A5,'Content Log'!$AC$5:$AC$504,"<="&AC5)) -> 46287|1 | AE5: =IF(A5="","",IFERROR(INDEX(Setup!$N$9:$N$14,MATCH(O5,Setup!$M$9:$M$14,0))&" ","")&IF(C5="","",TEXT(C5,"h:mm AM/PM")&" ")&D5&IF(H5="",""," · "&H5)) -> ✅ 9:00 AM Instagram · 5 mistakes killing your reach | AF5: =IF(OR(A5="",AA5=""),"",IF(AND(A5>=Dashboard!$G$4,A5<=Dashboard!$I$4),AA5+ROW()/10^9,"")) | AG5: =IF(A5="","",WEEKDAY(A5,2)) -> 2
A6: 46289 | B6: =IF(A6="","",TEXT(A6,"ddd")) -> Thu | C6: 0.75 | D6: TikTok | E6: Reel / Short video | F6: Entertain | G6: Evergreen | H6: POV: it's launch day | I6: POV: it's launch day and the link is broken 😅 | J6: =IF(I6="","",LEN(I6)) -> 45 | K6: Follow for part 2 | L6: TikTok – Trends | M6: =IF(L6="","",IFERROR(INDEX('Hashtag Bank'!$E$5:$E$104,MATCH(L6,'Hashtag Bank'!$B$5:$B$104,0)),"")) -> 4 | O6: Published | P6: Video editor | Q6: =IF(A6&H6="","",TRIM(IF(AND(A6<>"",A6<TODAY(),O6<>"Published",O6<>"Repurpose"),"⚠ Overdue ","")&IF(AND(J6<>"",D6<>"",IFERROR(J6>INDEX(Setup!$E$9:$E$18,MATCH(D6,Setup!$B$9:$B$18,0)),FALSE())),"✂ Caption too long ","")&IF(AND(M6<>"",D6<>"",IFERROR(M6>INDEX(Setup!$F$9:$F$18,MATCH(D6,Setup!$B$9:$B$18,0)),FALSE())),"# Too many tags",""))) | S6: 21800 | T6: 17400 | U6: 1490 | V6: 112 | W6: 240 | X6: 95 | Y6: 0 | Z6: =IF(COUNT(U6:X6)=0,"",SUM(U6:X6)) -> 1937 | AA6: =IF(OR(Z6="",N(T6)=0),"",Z6/T6) -> 0.11132184 | AC6: =IF(A6="","",A6+N(C6)+ROW()/10^7) -> 46289.75 | AD6: =IF(A6="","",TEXT(A6,"0")&"|"&COUNTIFS('Content Log'!$A$5:$A$504,A6,'Content Log'!$AC$5:$AC$504,"<="&AC6)) -> 46289|1 | AE6: =IF(A6="","",IFERROR(INDEX(Setup!$N$9:$N$14,MATCH(O6,Setup!$M$9:$M$14,0))&" ","")&IF(C6="","",TEXT(C6,"h:mm AM/PM")&" ")&D6&IF(H6="",""," · "&H6)) -> ✅ 6:00 PM TikTok · POV: it's launch day | AF6: =IF(OR(A6="",AA6=""),"",IF(AND(A6>=Dashboard!$G$4,A6<=Dashboard!$I$4),AA6+ROW()/10^9,"")) | AG6: =IF(A6="","",WEEKDAY(A6,2)) -> 4
A7: 46291 | B7: =IF(A7="","",TEXT(A7,"ddd")) -> Sat | C7: 0.5 | D7: LinkedIn | E7: Text post | F7: Inspire | G7: Founder story | H7: What 3 years of posting taught me | I7: Three years, 700 posts, one lesson: consistency beats virality. | J7: =IF(I7="","",LEN(I7)) -> 63 | K7: Comment your #1 lesson | L7: LI – Professional | M7: =IF(L7="","",IFERROR(INDEX('Hashtag Bank'!$E$5:$E$104,MATCH(L7,'Hashtag Bank'!$B$5:$B$104,0)),"")) -> 3 | O7: Published | P7: Me | Q7: =IF(A7&H7="","",TRIM(IF(AND(A7<>"",A7<TODAY(),O7<>"Published",O7<>"Repurpose"),"⚠ Overdue ","")&IF(AND(J7<>"",D7<>"",IFERROR(J7>INDEX(Setup!$E$9:$E$18,MATCH(D7,Setup!$B$9:$B$18,0)),FALSE())),"✂ Caption too long ","")&IF(AND(M7<>"",D7<>"",IFERROR(M7>INDEX(Setup!$F$9:$F$18,MATCH(D7,Setup!$B$9:$B$18,0)),FALSE())),"# Too many tags",""))) | S7: 5300 | T7: 3900 | U7: 210 | V7: 34 | W7: 18 | X7: 12 | Y7: 61 | Z7: =IF(COUNT(U7:X7)=0,"",SUM(U7:X7)) -> 274 | AA7: =IF(OR(Z7="",N(T7)=0),"",Z7/T7) -> 0.07025641 | AC7: =IF(A7="","",A7+N(C7)+ROW()/10^7) -> 46291.5 | AD7: =IF(A7="","",TEXT(A7,"0")&"|"&COUNTIFS('Content Log'!$A$5:$A$504,A7,'Content Log'!$AC$5:$AC$504,"<="&AC7)) -> 46291|1 | AE7: =IF(A7="","",IFERROR(INDEX(Setup!$N$9:$N$14,MATCH(O7,Setup!$M$9:$M$14,0))&" ","")&IF(C7="","",TEXT(C7,"h:mm AM/PM")&" ")&D7&IF(H7="",""," · "&H7)) -> ✅ 12:00 PM LinkedIn · What 3 years of posting taught me | AF7: =IF(OR(A7="",AA7=""),"",IF(AND(A7>=Dashboard!$G$4,A7<=Dashboard!$I$4),AA7+ROW()/10^9,"")) | AG7: =IF(A7="","",WEEKDAY(A7,2)) -> 6
A8: 46294 | B8: =IF(A8="","",TEXT(A8,"ddd")) -> Tue | C8: 0.41666667 | D8: Pinterest | E8: Pin | F8: Educate | G8: Evergreen | H8: Content calendar template | I8: Free content calendar template — plan a month in an hour. | J8: =IF(I8="","",LEN(I8)) -> 57 | K8: Download now | L8: Pinterest – SEO | M8: =IF(L8="","",IFERROR(INDEX('Hashtag Bank'!$E$5:$E$104,MATCH(L8,'Hashtag Bank'!$B$5:$B$104,0)),"")) -> 3 | O8: Published | P8: Designer | Q8: =IF(A8&H8="","",TRIM(IF(AND(A8<>"",A8<TODAY(),O8<>"Published",O8<>"Repurpose"),"⚠ Overdue ","")&IF(AND(J8<>"",D8<>"",IFERROR(J8>INDEX(Setup!$E$9:$E$18,MATCH(D8,Setup!$B$9:$B$18,0)),FALSE())),"✂ Caption too long ","")&IF(AND(M8<>"",D8<>"",IFERROR(M8>INDEX(Setup!$F$9:$F$18,MATCH(D8,Setup!$B$9:$B$18,0)),FALSE())),"# Too many tags",""))) | S8: 12600 | T8: 9800 | U8: 140 | V8: 3 | W8: 25 | X8: 410 | Y8: 288 | Z8: =IF(COUNT(U8:X8)=0,"",SUM(U8:X8)) -> 578 | AA8: =IF(OR(Z8="",N(T8)=0),"",Z8/T8) -> 0.058979592 | AC8: =IF(A8="","",A8+N(C8)+ROW()/10^7) -> 46294.417 | AD8: =IF(A8="","",TEXT(A8,"0")&"|"&COUNTIFS('Content Log'!$A$5:$A$504,A8,'Content Log'!$AC$5:$AC$504,"<="&AC8)) -> 46294|1 | AE8: =IF(A8="","",IFERROR(INDEX(Setup!$N$9:$N$14,MATCH(O8,Setup!$M$9:$M$14,0))&" ","")&IF(C8="","",TEXT(C8,"h:mm AM/PM")&" ")&D8&IF(H8="",""," · "&H8)) -> ✅ 10:00 AM Pinterest · Content calendar template | AF8: =IF(OR(A8="",AA8=""),"",IF(AND(A8>=Dashboard!$G$4,A8<=Dashboard!$I$4),AA8+ROW()/10^9,"")) | AG8: =IF(A8="","",WEEKDAY(A8,2)) -> 2
A9: 46296 | B9: =IF(A9="","",TEXT(A9,"ddd")) -> Thu | C9: 0.375 | D9: Instagram | E9: Reel / Short video | F9: Promote | G9: Fall Launch | H9: Sneak peek: something new | I9: Something new drops Oct 15 👀 Turn on notifications. | J9: =IF(I9="","",LEN(I9)) -> 51 | K9: Turn on notifications | L9: IG – Launch | M9: =IF(L9="","",IFERROR(INDEX('Hashtag Bank'!$E$5:$E$104,MATCH(L9,'Hashtag Bank'!$B$5:$B$104,0)),"")) -> 5 | O9: Published | P9: Video editor | Q9: =IF(A9&H9="","",TRIM(IF(AND(A9<>"",A9<TODAY(),O9<>"Published",O9<>"Repurpose"),"⚠ Overdue ","")&IF(AND(J9<>"",D9<>"",IFERROR(J9>INDEX(Setup!$E$9:$E$18,MATCH(D9,Setup!$B$9:$B$18,0)),FALSE())),"✂ Caption too long ","")&IF(AND(M9<>"",D9<>"",IFERROR(M9>INDEX(Setup!$F$9:$F$18,MATCH(D9,Setup!$B$9:$B$18,0)),FALSE())),"# Too many tags",""))) | S9: 15400 | T9: 11900 | U9: 980 | V9: 87 | W9: 130 | X9: 210 | Y9: 155 | Z9: =IF(COUNT(U9:X9)=0,"",SUM(U9:X9)) -> 1407 | AA9: =IF(OR(Z9="",N(T9)=0),"",Z9/T9) -> 0.11823529 | AC9: =IF(A9="","",A9+N(C9)+ROW()/10^7) -> 46296.375 | AD9: =IF(A9="","",TEXT(A9,"0")&"|"&COUNTIFS('Content Log'!$A$5:$A$504,A9,'Content Log'!$AC$5:$AC$504,"<="&AC9)) -> 46296|1 | AE9: =IF(A9="","",IFERROR(INDEX(Setup!$N$9:$N$14,MATCH(O9,Setup!$M$9:$M$14,0))&" ","")&IF(C9="","",TEXT(C9,"h:mm AM/PM")&" ")&D9&IF(H9="",""," · "&H9)) -> ✅ 9:00 AM Instagram · Sneak peek: something new | AF9: =IF(OR(A9="",AA9=""),"",IF(AND(A9>=Dashboard!$G$4,A9<=Dashboard!$I$4),AA9+ROW()/10^9,"")) -> 0.1182353 | AG9: =IF(A9="","",WEEKDAY(A9,2)) -> 4
A10: 46296 | B10: =IF(A10="","",TEXT(A10,"ddd")) -> Thu | C10: 0.70833333 | D10: Threads | E10: Text post | F10: Community | H10: Ask me anything Friday | I10: AMA: content strategy, tools, burnout. Go 👇 | J10: =IF(I10="","",LEN(I10)) -> 43 | K10: Reply below | M10: =IF(L10="","",IFERROR(INDEX('Hashtag Bank'!$E$5:$E$104,MATCH(L10,'Hashtag Bank'!$B$5:$B$104,0)),"")) | O10: Published | P10: Me | Q10: =IF(A10&H10="","",TRIM(IF(AND(A10<>"",A10<TODAY(),O10<>"Published",O10<>"Repurpose"),"⚠ Overdue ","")&IF(AND(J10<>"",D10<>"",IFERROR(J10>INDEX(Setup!$E$9:$E$18,MATCH(D10,Setup!$B$9:$B$18,0)),FALSE())),"✂ Caption too long ","")&IF(AND(M10<>"",D10<>"",IFERROR(M10>INDEX(Setup!$F$9:$F$18,MATCH(D10,Setup!$B$9:$B$18,0)),FALSE())),"# Too many tags",""))) | S10: 2100 | T10: 1700 | U10: 96 | V10: 71 | W10: 4 | X10: 2 | Y10: 0 | Z10: =IF(COUNT(U10:X10)=0,"",SUM(U10:X10)) -> 173 | AA10: =IF(OR(Z10="",N(T10)=0),"",Z10/T10) -> 0.10176471 | AC10: =IF(A10="","",A10+N(C10)+ROW()/10^7) -> 46296.708 | AD10: =IF(A10="","",TEXT(A10,"0")&"|"&COUNTIFS('Content Log'!$A$5:$A$504,A10,'Content Log'!$AC$5:$AC$504,"<="&AC10)) -> 46296|2 | AE10: =IF(A10="","",IFERROR(INDEX(Setup!$N$9:$N$14,MATCH(O10,Setup!$M$9:$M$14,0))&" ","")&IF(C10="","",TEXT(C10,"h:mm AM/PM")&" ")&D10&IF(H10="",""," · "&H10)) -> ✅ 5:00 PM Threads · Ask me anything Friday | AF10: =IF(OR(A10="",AA10=""),"",IF(AND(A10>=Dashboard!$G$4,A10<=Dashboard!$I$4),AA10+ROW()/10^9,"")) -> 0.10176472 | AG10: =IF(A10="","",WEEKDAY(A10,2)) -> 4
A11: 46297 | B11: =IF(A11="","",TEXT(A11,"ddd")) -> Fri | C11: 0.45833333 | D11: Facebook | E11: Single image | F11: Community | H11: Customer spotlight: Maya | I11: Meet Maya, who grew her shop 3x in 6 months using batching. | J11: =IF(I11="","",LEN(I11)) -> 59 | K11: Share your story | M11: =IF(L11="","",IFERROR(INDEX('Hashtag Bank'!$E$5:$E$104,MATCH(L11,'Hashtag Bank'!$B$5:$B$104,0)),"")) | O11: Drafting | P11: VA | Q11: =IF(A11&H11="","",TRIM(IF(AND(A11<>"",A11<TODAY(),O11<>"Published",O11<>"Repurpose"),"⚠ Overdue ","")&IF(AND(J11<>"",D11<>"",IFERROR(J11>INDEX(Setup!$E$9:$E$18,MATCH(D11,Setup!$B$9:$B$18,0)),FALSE())),"✂ Caption too long ","")&IF(AND(M11<>"",D11<>"",IFERROR(M11>INDEX(Setup!$F$9:$F$18,MATCH(D11,Setup!$B$9:$B$18,0)),FALSE())),"# Too many tags",""))) -> ⚠ Overdue | Z11: =IF(COUNT(U11:X11)=0,"",SUM(U11:X11)) | AA11: =IF(OR(Z11="",N(T11)=0),"",Z11/T11) | AC11: =IF(A11="","",A11+N(C11)+ROW()/10^7) -> 46297.458 | AD11: =IF(A11="","",TEXT(A11,"0")&"|"&COUNTIFS('Content Log'!$A$5:$A$504,A11,'Content Log'!$AC$5:$AC$504,"<="&AC11)) -> 46297|1 | AE11: =IF(A11="","",IFERROR(INDEX(Setup!$N$9:$N$14,MATCH(O11,Setup!$M$9:$M$14,0))&" ","")&IF(C11="","",TEXT(C11,"h:mm AM/PM")&" ")&D11&IF(H11="",""," · "&H11)) -> ✏️ 11:00 AM Facebook · Customer spotlight: Maya | AF11: =IF(OR(A11="",AA11=""),"",IF(AND(A11>=Dashboard!$G$4,A11<=Dashboard!$I$4),AA11+ROW()/10^9,"")) | AG11: =IF(A11="","",WEEKDAY(A11,2)) -> 5
A12: 46298 | B12: =IF(A12="","",TEXT(A12,"ddd")) -> Sat | C12: 0.58333333 | D12: YouTube | E12: Long-form video | F12: Educate | G12: Evergreen | H12: How I batch 30 posts in a day | I12: Full walkthrough of my batching system + free template. | J12: =IF(I12="","",LEN(I12)) -> 55 | K12: Subscribe | L12: YT – Tutorials | M12: =IF(L12="","",IFERROR(INDEX('Hashtag Bank'!$E$5:$E$104,MATCH(L12,'Hashtag Bank'!$B$5:$B$104,0)),"")) -> 3 | O12: Published | P12: Video editor | Q12: =IF(A12&H12="","",TRIM(IF(AND(A12<>"",A12<TODAY(),O12<>"Published",O12<>"Repurpose"),"⚠ Overdue ","")&IF(AND(J12<>"",D12<>"",IFERROR(J12>INDEX(Setup!$E$9:$E$18,MATCH(D12,Setup!$B$9:$B$18,0)),FALSE())),"✂ Caption too long ","")&IF(AND(M12<>"",D12<>"",IFERROR(M12>INDEX(Setup!$F$9:$F$18,MATCH(D12,Setup!$B$9:$B$18,0)),FALSE())),"# Too many tags",""))) | S12: 9800 | T12: 7400 | U12: 620 | V12: 95 | W12: 41 | X12: 188 | Y12: 302 | Z12: =IF(COUNT(U12:X12)=0,"",SUM(U12:X12)) -> 944 | AA12: =IF(OR(Z12="",N(T12)=0),"",Z12/T12) -> 0.12756757 | AC12: =IF(A12="","",A12+N(C12)+ROW()/10^7) -> 46298.583 | AD12: =IF(A12="","",TEXT(A12,"0")&"|"&COUNTIFS('Content Log'!$A$5:$A$504,A12,'Content Log'!$AC$5:$AC$504,"<="&AC12)) -> 46298|1 | AE12: =IF(A12="","",IFERROR(INDEX(Setup!$N$9:$N$14,MATCH(O12,Setup!$M$9:$M$14,0))&" ","")&IF(C12="","",TEXT(C12,"h:mm AM/PM")&" ")&D12&IF(H12="",""," · "&H12)) -> ✅ 2:00 PM YouTube · How I batch 30 posts in a day | AF12: =IF(OR(A12="",AA12=""),"",IF(AND(A12>=Dashboard!$G$4,A12<=Dashboard!$I$4),AA12+ROW()/10^9,"")) -> 0.12756758 | AG12: =IF(A12="","",WEEKDAY(A12,2)) -> 6
A13: 46298 | B13: =IF(A13="","",TEXT(A13,"ddd")) -> Sat | C13: 0.79166667 | D13: TikTok | E13: Reel / Short video | F13: Entertain | H13: Trend: 'tell me without telling me' | I13: Tell me you're a content creator without telling me… | J13: =IF(I13="","",LEN(I13)) -> 52 | K13: Duet this | L13: TikTok – Trends | M13: =IF(L13="","",IFERROR(INDEX('Hashtag Bank'!$E$5:$E$104,MATCH(L13,'Hashtag Bank'!$B$5:$B$104,0)),"")) -> 4 | O13: Published | P13: Video editor | Q13: =IF(A13&H13="","",TRIM(IF(AND(A13<>"",A13<TODAY(),O13<>"Published",O13<>"Repurpose"),"⚠ Overdue ","")&IF(AND(J13<>"",D13<>"",IFERROR(J13>INDEX(Setup!$E$9:$E$18,MATCH(D13,Setup!$B$9:$B$18,0)),FALSE())),"✂ Caption too long ","")&IF(AND(M13<>"",D13<>"",IFERROR(M13>INDEX(Setup!$F$9:$F$18,MATCH(D13,Setup!$B$9:$B$18,0)),FALSE())),"# Too many tags",""))) | S13: 30500 | T13: 26100 | U13: 2390 | V13: 204 | W13: 410 | X13: 120 | Y13: 0 | Z13: =IF(COUNT(U13:X13)=0,"",SUM(U13:X13)) -> 3124 | AA13: =IF(OR(Z13="",N(T13)=0),"",Z13/T13) -> 0.11969349 | AC13: =IF(A13="","",A13+N(C13)+ROW()/10^7) -> 46298.792 | AD13: =IF(A13="","",TEXT(A13,"0")&"|"&COUNTIFS('Content Log'!$A$5:$A$504,A13,'Content Log'!$AC$5:$AC$504,"<="&AC13)) -> 46298|2 | AE13: =IF(A13="","",IFERROR(INDEX(Setup!$N$9:$N$14,MATCH(O13,Setup!$M$9:$M$14,0))&" ","")&IF(C13="","",TEXT(C13,"h:mm AM/PM")&" ")&D13&IF(H13="",""," · "&H13)) -> ✅ 7:00 PM TikTok · Trend: 'tell me without telling me' | AF13: =IF(OR(A13="",AA13=""),"",IF(AND(A13>=Dashboard!$G$4,A13<=Dashboard!$I$4),AA13+ROW()/10^9,"")) -> 0.1196935 | AG13: =IF(A13="","",WEEKDAY(A13,2)) -> 6
A14: 46300 | B14: =IF(A14="","",TEXT(A14,"ddd")) -> Mon | C14: 0.375 | D14: Instagram | E14: Story | F14: Community | H14: Poll: which colourway? | I14: Poll: sage or blush for the new planner? | J14: =IF(I14="","",LEN(I14)) -> 40 | K14: Vote | M14: =IF(L14="","",IFERROR(INDEX('Hashtag Bank'!$E$5:$E$104,MATCH(L14,'Hashtag Bank'!$B$5:$B$104,0)),"")) | O14: Scheduled | P14: Me | Q14: =IF(A14&H14="","",TRIM(IF(AND(A14<>"",A14<TODAY(),O14<>"Published",O14<>"Repurpose"),"⚠ Overdue ","")&IF(AND(J14<>"",D14<>"",IFERROR(J14>INDEX(Setup!$E$9:$E$18,MATCH(D14,Setup!$B$9:$B$18,0)),FALSE())),"✂ Caption too long ","")&IF(AND(M14<>"",D14<>"",IFERROR(M14>INDEX(Setup!$F$9:$F$18,MATCH(D14,Setup!$B$9:$B$18,0)),FALSE())),"# Too many tags",""))) | Z14: =IF(COUNT(U14:X14)=0,"",SUM(U14:X14)) | AA14: =IF(OR(Z14="",N(T14)=0),"",Z14/T14) | AC14: =IF(A14="","",A14+N(C14)+ROW()/10^7) -> 46300.375 | AD14: =IF(A14="","",TEXT(A14,"0")&"|"&COUNTIFS('Content Log'!$A$5:$A$504,A14,'Content Log'!$AC$5:$AC$504,"<="&AC14)) -> 46300|1 | AE14: =IF(A14="","",IFERROR(INDEX(Setup!$N$9:$N$14,MATCH(O14,Setup!$M$9:$M$14,0))&" ","")&IF(C14="","",TEXT(C14,"h:mm AM/PM")&" ")&D14&IF(H14="",""," · "&H14)) -> 🕒 9:00 AM Instagram · Poll: which colourway? | AF14: =IF(OR(A14="",AA14=""),"",IF(AND(A14>=Dashboard!$G$4,A14<=Dashboard!$I$4),AA14+ROW()/10^9,"")) | AG14: =IF(A14="","",WEEKDAY(A14,2)) -> 1
A15: 46301 | B15: =IF(A15="","",TEXT(A15,"ddd")) -> Tue | C15: 0.5 | D15: LinkedIn | E15: Carousel | F15: Educate | G15: Evergreen | H15: The 4-pillar content framework | I15: Educate, Inspire, Entertain, Promote — here's the mix that works. | J15: =IF(I15="","",LEN(I15)) -> 65 | K15: Repost if useful | L15: LI – Professional | M15: =IF(L15="","",IFERROR(INDEX('Hashtag Bank'!$E$5:$E$104,MATCH(L15,'Hashtag Bank'!$B$5:$B$104,0)),"")) -> 3 | O15: Scheduled | P15: Designer | Q15: =IF(A15&H15="","",TRIM(IF(AND(A15<>"",A15<TODAY(),O15<>"Published",O15<>"Repurpose"),"⚠ Overdue ","")&IF(AND(J15<>"",D15<>"",IFERROR(J15>INDEX(Setup!$E$9:$E$18,MATCH(D15,Setup!$B$9:$B$18,0)),FALSE())),"✂ Caption too long ","")&IF(AND(M15<>"",D15<>"",IFERROR(M15>INDEX(Setup!$F$9:$F$18,MATCH(D15,Setup!$B$9:$B$18,0)),FALSE())),"# Too many tags",""))) | Z15: =IF(COUNT(U15:X15)=0,"",SUM(U15:X15)) | AA15: =IF(OR(Z15="",N(T15)=0),"",Z15/T15) | AC15: =IF(A15="","",A15+N(C15)+ROW()/10^7) -> 46301.5 | AD15: =IF(A15="","",TEXT(A15,"0")&"|"&COUNTIFS('Content Log'!$A$5:$A$504,A15,'Content Log'!$AC$5:$AC$504,"<="&AC15)) -> 46301|1 | AE15: =IF(A15="","",IFERROR(INDEX(Setup!$N$9:$N$14,MATCH(O15,Setup!$M$9:$M$14,0))&" ","")&IF(C15="","",TEXT(C15,"h:mm AM/PM")&" ")&D15&IF(H15="",""," · "&H15)) -> 🕒 12:00 PM LinkedIn · The 4-pillar content framework | AF15: =IF(OR(A15="",AA15=""),"",IF(AND(A15>=Dashboard!$G$4,A15<=Dashboard!$I$4),AA15+ROW()/10^9,"")) | AG15: =IF(A15="","",WEEKDAY(A15,2)) -> 2
A16: 46302 | B16: =IF(A16="","",TEXT(A16,"ddd")) -> Wed | C16: 0.77083333 | D16: X / Twitter | E16: Thread | F16: Educate | G16: Evergreen | H16: Thread: my posting workflow | I16: A thread on exactly how I plan, batch, schedule and review a full month of content across six platforms without losing my mind — including the spreadsheet I use, the review cadence, and the three metrics I actually look at every Friday afternoon to decide what to make more of next month. | J16: =IF(I16="","",LEN(I16)) -> 288 | K16: Follow for more | L16: X – Short | M16: =IF(L16="","",IFERROR(INDEX('Hashtag Bank'!$E$5:$E$104,MATCH(L16,'Hashtag Bank'!$B$5:$B$104,0)),"")) -> 1 | O16: In Review | P16: Me | Q16: =IF(A16&H16="","",TRIM(IF(AND(A16<>"",A16<TODAY(),O16<>"Published",O16<>"Repurpose"),"⚠ Overdue ","")&IF(AND(J16<>"",D16<>"",IFERROR(J16>INDEX(Setup!$E$9:$E$18,MATCH(D16,Setup!$B$9:$B$18,0)),FALSE())),"✂ Caption too long ","")&IF(AND(M16<>"",D16<>"",IFERROR(M16>INDEX(Setup!$F$9:$F$18,MATCH(D16,Setup!$B$9:$B$18,0)),FALSE())),"# Too many tags",""))) -> ✂ Caption too long | Z16: =IF(COUNT(U16:X16)=0,"",SUM(U16:X16)) | AA16: =IF(OR(Z16="",N(T16)=0),"",Z16/T16) | AC16: =IF(A16="","",A16+N(C16)+ROW()/10^7) -> 46302.771 | AD16: =IF(A16="","",TEXT(A16,"0")&"|"&COUNTIFS('Content Log'!$A$5:$A$504,A16,'Content Log'!$AC$5:$AC$504,"<="&AC16)) -> 46302|1 | AE16: =IF(A16="","",IFERROR(INDEX(Setup!$N$9:$N$14,MATCH(O16,Setup!$M$9:$M$14,0))&" ","")&IF(C16="","",TEXT(C16,"h:mm AM/PM")&" ")&D16&IF(H16="",""," · "&H16)) -> 👀 6:30 PM X / Twitter · Thread: my posting workflow | AF16: =IF(OR(A16="",AA16=""),"",IF(AND(A16>=Dashboard!$G$4,A16<=Dashboard!$I$4),AA16+ROW()/10^9,"")) | AG16: =IF(A16="","",WEEKDAY(A16,2)) -> 3
A17: 46303 | B17: =IF(A17="","",TEXT(A17,"ddd")) -> Thu | C17: 0.41666667 | D17: Pinterest | E17: Pin | F17: Inspire | G17: Fall Launch | H17: Cozy fall desk setup | I17: Cozy fall desk setup for focused planning days 🍂 | J17: =IF(I17="","",LEN(I17)) -> 48 | K17: Save this pin | L17: Pinterest – SEO | M17: =IF(L17="","",IFERROR(INDEX('Hashtag Bank'!$E$5:$E$104,MATCH(L17,'Hashtag Bank'!$B$5:$B$104,0)),"")) -> 3 | O17: Scheduled | P17: Designer | Q17: =IF(A17&H17="","",TRIM(IF(AND(A17<>"",A17<TODAY(),O17<>"Published",O17<>"Repurpose"),"⚠ Overdue ","")&IF(AND(J17<>"",D17<>"",IFERROR(J17>INDEX(Setup!$E$9:$E$18,MATCH(D17,Setup!$B$9:$B$18,0)),FALSE())),"✂ Caption too long ","")&IF(AND(M17<>"",D17<>"",IFERROR(M17>INDEX(Setup!$F$9:$F$18,MATCH(D17,Setup!$B$9:$B$18,0)),FALSE())),"# Too many tags",""))) | Z17: =IF(COUNT(U17:X17)=0,"",SUM(U17:X17)) | AA17: =IF(OR(Z17="",N(T17)=0),"",Z17/T17) | AC17: =IF(A17="","",A17+N(C17)+ROW()/10^7) -> 46303.417 | AD17: =IF(A17="","",TEXT(A17,"0")&"|"&COUNTIFS('Content Log'!$A$5:$A$504,A17,'Content Log'!$AC$5:$AC$504,"<="&AC17)) -> 46303|1 | AE17: =IF(A17="","",IFERROR(INDEX(Setup!$N$9:$N$14,MATCH(O17,Setup!$M$9:$M$14,0))&" ","")&IF(C17="","",TEXT(C17,"h:mm AM/PM")&" ")&D17&IF(H17="",""," · "&H17)) -> 🕒 10:00 AM Pinterest · Cozy fall desk setup | AF17: =IF(OR(A17="",AA17=""),"",IF(AND(A17>=Dashboard!$G$4,A17<=Dashboard!$I$4),AA17+ROW()/10^9,"")) | AG17: =IF(A17="","",WEEKDAY(A17,2)) -> 4
A18: 46304 | B18: =IF(A18="","",TEXT(A18,"ddd")) -> Fri | C18: 0.70833333 | D18: Instagram | E18: Reel / Short video | F18: Entertain | H18: Day in the life of a planner shop | J18: =IF(I18="","",LEN(I18)) | K18: Follow | L18: IG – Growth tips | M18: =IF(L18="","",IFERROR(INDEX('Hashtag Bank'!$E$5:$E$104,MATCH(L18,'Hashtag Bank'!$B$5:$B$104,0)),"")) -> 8 | O18: Drafting | P18: Video editor | Q18: =IF(A18&H18="","",TRIM(IF(AND(A18<>"",A18<TODAY(),O18<>"Published",O18<>"Repurpose"),"⚠ Overdue ","")&IF(AND(J18<>"",D18<>"",IFERROR(J18>INDEX(Setup!$E$9:$E$18,MATCH(D18,Setup!$B$9:$B$18,0)),FALSE())),"✂ Caption too long ","")&IF(AND(M18<>"",D18<>"",IFERROR(M18>INDEX(Setup!$F$9:$F$18,MATCH(D18,Setup!$B$9:$B$18,0)),FALSE())),"# Too many tags",""))) | Z18: =IF(COUNT(U18:X18)=0,"",SUM(U18:X18)) | AA18: =IF(OR(Z18="",N(T18)=0),"",Z18/T18) | AC18: =IF(A18="","",A18+N(C18)+ROW()/10^7) -> 46304.708 | AD18: =IF(A18="","",TEXT(A18,"0")&"|"&COUNTIFS('Content Log'!$A$5:$A$504,A18,'Content Log'!$AC$5:$AC$504,"<="&AC18)) -> 46304|1 | AE18: =IF(A18="","",IFERROR(INDEX(Setup!$N$9:$N$14,MATCH(O18,Setup!$M$9:$M$14,0))&" ","")&IF(C18="","",TEXT(C18,"h:mm AM/PM")&" ")&D18&IF(H18="",""," · "&H18)) -> ✏️ 5:00 PM Instagram · Day in the life of a planner shop | AF18: =IF(OR(A18="",AA18=""),"",IF(AND(A18>=Dashboard!$G$4,A18<=Dashboard!$I$4),AA18+ROW()/10^9,"")) | AG18: =IF(A18="","",WEEKDAY(A18,2)) -> 5
A19: 46307 | B19: =IF(A19="","",TEXT(A19,"ddd")) -> Mon | C19: 0.375 | D19: Instagram | E19: Carousel | F19: Educate | G19: Fall Launch | H19: How to plan Q4 content | J19: =IF(I19="","",LEN(I19)) | K19: Save for Q4 | L19: IG – Growth tips | M19: =IF(L19="","",IFERROR(INDEX('Hashtag Bank'!$E$5:$E$104,MATCH(L19,'Hashtag Bank'!$B$5:$B$104,0)),"")) -> 8 | O19: Drafting | P19: Designer | Q19: =IF(A19&H19="","",TRIM(IF(AND(A19<>"",A19<TODAY(),O19<>"Published",O19<>"Repurpose"),"⚠ Overdue ","")&IF(AND(J19<>"",D19<>"",IFERROR(J19>INDEX(Setup!$E$9:$E$18,MATCH(D19,Setup!$B$9:$B$18,0)),FALSE())),"✂ Caption too long ","")&IF(AND(M19<>"",D19<>"",IFERROR(M19>INDEX(Setup!$F$9:$F$18,MATCH(D19,Setup!$B$9:$B$18,0)),FALSE())),"# Too many tags",""))) | Z19: =IF(COUNT(U19:X19)=0,"",SUM(U19:X19)) | AA19: =IF(OR(Z19="",N(T19)=0),"",Z19/T19) | AC19: =IF(A19="","",A19+N(C19)+ROW()/10^7) -> 46307.375 | AD19: =IF(A19="","",TEXT(A19,"0")&"|"&COUNTIFS('Content Log'!$A$5:$A$504,A19,'Content Log'!$AC$5:$AC$504,"<="&AC19)) -> 46307|1 | AE19: =IF(A19="","",IFERROR(INDEX(Setup!$N$9:$N$14,MATCH(O19,Setup!$M$9:$M$14,0))&" ","")&IF(C19="","",TEXT(C19,"h:mm AM/PM")&" ")&D19&IF(H19="",""," · "&H19)) -> ✏️ 9:00 AM Instagram · How to plan Q4 content | AF19: =IF(OR(A19="",AA19=""),"",IF(AND(A19>=Dashboard!$G$4,A19<=Dashboard!$I$4),AA19+ROW()/10^9,"")) | AG19: =IF(A19="","",WEEKDAY(A19,2)) -> 1
A20: 46308 | B20: =IF(A20="","",TEXT(A20,"ddd")) -> Tue | C20: 0.5 | D20: TikTok | E20: Reel / Short video | F20: Promote | G20: Fall Launch | H20: Countdown: 2 days | J20: =IF(I20="","",LEN(I20)) | K20: Link in bio | L20: TikTok – Trends | M20: =IF(L20="","",IFERROR(INDEX('Hashtag Bank'!$E$5:$E$104,MATCH(L20,'Hashtag Bank'!$B$5:$B$104,0)),"")) -> 4 | O20: Idea | P20: Video editor | Q20: =IF(A20&H20="","",TRIM(IF(AND(A20<>"",A20<TODAY(),O20<>"Published",O20<>"Repurpose"),"⚠ Overdue ","")&IF(AND(J20<>"",D20<>"",IFERROR(J20>INDEX(Setup!$E$9:$E$18,MATCH(D20,Setup!$B$9:$B$18,0)),FALSE())),"✂ Caption too long ","")&IF(AND(M20<>"",D20<>"",IFERROR(M20>INDEX(Setup!$F$9:$F$18,MATCH(D20,Setup!$B$9:$B$18,0)),FALSE())),"# Too many tags",""))) | Z20: =IF(COUNT(U20:X20)=0,"",SUM(U20:X20)) | AA20: =IF(OR(Z20="",N(T20)=0),"",Z20/T20) | AC20: =IF(A20="","",A20+N(C20)+ROW()/10^7) -> 46308.5 | AD20: =IF(A20="","",TEXT(A20,"0")&"|"&COUNTIFS('Content Log'!$A$5:$A$504,A20,'Content Log'!$AC$5:$AC$504,"<="&AC20)) -> 46308|1 | AE20: =IF(A20="","",IFERROR(INDEX(Setup!$N$9:$N$14,MATCH(O20,Setup!$M$9:$M$14,0))&" ","")&IF(C20="","",TEXT(C20,"h:mm AM/PM")&" ")&D20&IF(H20="",""," · "&H20)) -> 💡 12:00 PM TikTok · Countdown: 2 days | AF20: =IF(OR(A20="",AA20=""),"",IF(AND(A20>=Dashboard!$G$4,A20<=Dashboard!$I$4),AA20+ROW()/10^9,"")) | AG20: =IF(A20="","",WEEKDAY(A20,2)) -> 2
A21: 46310 | B21: =IF(A21="","",TEXT(A21,"ddd")) -> Thu | C21: 0.33333333 | D21: Instagram | E21: Reel / Short video | F21: Promote | G21: Fall Launch | H21: LAUNCH DAY 🎉 | I21: It's here! The planner that fills itself in. | J21: =IF(I21="","",LEN(I21)) -> 44 | K21: Shop now — link in bio | L21: IG – Launch | M21: =IF(L21="","",IFERROR(INDEX('Hashtag Bank'!$E$5:$E$104,MATCH(L21,'Hashtag Bank'!$B$5:$B$104,0)),"")) -> 5 | O21: Scheduled | P21: Me | Q21: =IF(A21&H21="","",TRIM(IF(AND(A21<>"",A21<TODAY(),O21<>"Published",O21<>"Repurpose"),"⚠ Overdue ","")&IF(AND(J21<>"",D21<>"",IFERROR(J21>INDEX(Setup!$E$9:$E$18,MATCH(D21,Setup!$B$9:$B$18,0)),FALSE())),"✂ Caption too long ","")&IF(AND(M21<>"",D21<>"",IFERROR(M21>INDEX(Setup!$F$9:$F$18,MATCH(D21,Setup!$B$9:$B$18,0)),FALSE())),"# Too many tags",""))) | Z21: =IF(COUNT(U21:X21)=0,"",SUM(U21:X21)) | AA21: =IF(OR(Z21="",N(T21)=0),"",Z21/T21) | AC21: =IF(A21="","",A21+N(C21)+ROW()/10^7) -> 46310.333 | AD21: =IF(A21="","",TEXT(A21,"0")&"|"&COUNTIFS('Content Log'!$A$5:$A$504,A21,'Content Log'!$AC$5:$AC$504,"<="&AC21)) -> 46310|1 | AE21: =IF(A21="","",IFERROR(INDEX(Setup!$N$9:$N$14,MATCH(O21,Setup!$M$9:$M$14,0))&" ","")&IF(C21="","",TEXT(C21,"h:mm AM/PM")&" ")&D21&IF(H21="",""," · "&H21)) -> 🕒 8:00 AM Instagram · LAUNCH DAY 🎉 | AF21: =IF(OR(A21="",AA21=""),"",IF(AND(A21>=Dashboard!$G$4,A21<=Dashboard!$I$4),AA21+ROW()/10^9,"")) | AG21: =IF(A21="","",WEEKDAY(A21,2)) -> 4
A22: 46310 | B22: =IF(A22="","",TEXT(A22,"ddd")) -> Thu | C22: 0.5 | D22: Facebook | E22: Single image | F22: Promote | G22: Fall Launch | H22: Launch announcement | J22: =IF(I22="","",LEN(I22)) | K22: Shop now | M22: =IF(L22="","",IFERROR(INDEX('Hashtag Bank'!$E$5:$E$104,MATCH(L22,'Hashtag Bank'!$B$5:$B$104,0)),"")) | O22: Scheduled | P22: VA | Q22: =IF(A22&H22="","",TRIM(IF(AND(A22<>"",A22<TODAY(),O22<>"Published",O22<>"Repurpose"),"⚠ Overdue ","")&IF(AND(J22<>"",D22<>"",IFERROR(J22>INDEX(Setup!$E$9:$E$18,MATCH(D22,Setup!$B$9:$B$18,0)),FALSE())),"✂ Caption too long ","")&IF(AND(M22<>"",D22<>"",IFERROR(M22>INDEX(Setup!$F$9:$F$18,MATCH(D22,Setup!$B$9:$B$18,0)),FALSE())),"# Too many tags",""))) | Z22: =IF(COUNT(U22:X22)=0,"",SUM(U22:X22)) | AA22: =IF(OR(Z22="",N(T22)=0),"",Z22/T22) | AC22: =IF(A22="","",A22+N(C22)+ROW()/10^7) -> 46310.5 | AD22: =IF(A22="","",TEXT(A22,"0")&"|"&COUNTIFS('Content Log'!$A$5:$A$504,A22,'Content Log'!$AC$5:$AC$504,"<="&AC22)) -> 46310|2 | AE22: =IF(A22="","",IFERROR(INDEX(Setup!$N$9:$N$14,MATCH(O22,Setup!$M$9:$M$14,0))&" ","")&IF(C22="","",TEXT(C22,"h:mm AM/PM")&" ")&D22&IF(H22="",""," · "&H22)) -> 🕒 12:00 PM Facebook · Launch announcement | AF22: =IF(OR(A22="",AA22=""),"",IF(AND(A22>=Dashboard!$G$4,A22<=Dashboard!$I$4),AA22+ROW()/10^9,"")) | AG22: =IF(A22="","",WEEKDAY(A22,2)) -> 4
A23: 46310 | B23: =IF(A23="","",TEXT(A23,"ddd")) -> Thu | C23: 0.75 | D23: LinkedIn | E23: Text post | F23: Inspire | G23: Fall Launch | H23: Why we built this | J23: =IF(I23="","",LEN(I23)) | K23: Read the story | L23: LI – Professional | M23: =IF(L23="","",IFERROR(INDEX('Hashtag Bank'!$E$5:$E$104,MATCH(L23,'Hashtag Bank'!$B$5:$B$104,0)),"")) -> 3 | O23: Drafting | P23: Me | Q23: =IF(A23&H23="","",TRIM(IF(AND(A23<>"",A23<TODAY(),O23<>"Published",O23<>"Repurpose"),"⚠ Overdue ","")&IF(AND(J23<>"",D23<>"",IFERROR(J23>INDEX(Setup!$E$9:$E$18,MATCH(D23,Setup!$B$9:$B$18,0)),FALSE())),"✂ Caption too long ","")&IF(AND(M23<>"",D23<>"",IFERROR(M23>INDEX(Setup!$F$9:$F$18,MATCH(D23,Setup!$B$9:$B$18,0)),FALSE())),"# Too many tags",""))) | Z23: =IF(COUNT(U23:X23)=0,"",SUM(U23:X23)) | AA23: =IF(OR(Z23="",N(T23)=0),"",Z23/T23) | AC23: =IF(A23="","",A23+N(C23)+ROW()/10^7) -> 46310.75 | AD23: =IF(A23="","",TEXT(A23,"0")&"|"&COUNTIFS('Content Log'!$A$5:$A$504,A23,'Content Log'!$AC$5:$AC$504,"<="&AC23)) -> 46310|3 | AE23: =IF(A23="","",IFERROR(INDEX(Setup!$N$9:$N$14,MATCH(O23,Setup!$M$9:$M$14,0))&" ","")&IF(C23="","",TEXT(C23,"h:mm AM/PM")&" ")&D23&IF(H23="",""," · "&H23)) -> ✏️ 6:00 PM LinkedIn · Why we built this | AF23: =IF(OR(A23="",AA23=""),"",IF(AND(A23>=Dashboard!$G$4,A23<=Dashboard!$I$4),AA23+ROW()/10^9,"")) | AG23: =IF(A23="","",WEEKDAY(A23,2)) -> 4
A24: 46310 | B24: =IF(A24="","",TEXT(A24,"ddd")) -> Thu | C24: 0.83333333 | D24: Threads | E24: Text post | F24: Promote | G24: Fall Launch | H24: We're live! | J24: =IF(I24="","",LEN(I24)) | M24: =IF(L24="","",IFERROR(INDEX('Hashtag Bank'!$E$5:$E$104,MATCH(L24,'Hashtag Bank'!$B$5:$B$104,0)),"")) | O24: Idea | P24: Me | Q24: =IF(A24&H24="","",TRIM(IF(AND(A24<>"",A24<TODAY(),O24<>"Published",O24<>"Repurpose"),"⚠ Overdue ","")&IF(AND(J24<>"",D24<>"",IFERROR(J24>INDEX(Setup!$E$9:$E$18,MATCH(D24,Setup!$B$9:$B$18,0)),FALSE())),"✂ Caption too long ","")&IF(AND(M24<>"",D24<>"",IFERROR(M24>INDEX(Setup!$F$9:$F$18,MATCH(D24,Setup!$B$9:$B$18,0)),FALSE())),"# Too many tags",""))) | Z24: =IF(COUNT(U24:X24)=0,"",SUM(U24:X24)) | AA24: =IF(OR(Z24="",N(T24)=0),"",Z24/T24) | AC24: =IF(A24="","",A24+N(C24)+ROW()/10^7) -> 46310.833 | AD24: =IF(A24="","",TEXT(A24,"0")&"|"&COUNTIFS('Content Log'!$A$5:$A$504,A24,'Content Log'!$AC$5:$AC$504,"<="&AC24)) -> 46310|4 | AE24: =IF(A24="","",IFERROR(INDEX(Setup!$N$9:$N$14,MATCH(O24,Setup!$M$9:$M$14,0))&" ","")&IF(C24="","",TEXT(C24,"h:mm AM/PM")&" ")&D24&IF(H24="",""," · "&H24)) -> 💡 8:00 PM Threads · We're live! | AF24: =IF(OR(A24="",AA24=""),"",IF(AND(A24>=Dashboard!$G$4,A24<=Dashboard!$I$4),AA24+ROW()/10^9,"")) | AG24: =IF(A24="","",WEEKDAY(A24,2)) -> 4
A25: 46315 | B25: =IF(A25="","",TEXT(A25,"ddd")) -> Tue | C25: 0.58333333 | D25: YouTube | E25: Long-form video | F25: Educate | H25: Q4 content strategy masterclass | J25: =IF(I25="","",LEN(I25)) | K25: Subscribe | L25: YT – Tutorials | M25: =IF(L25="","",IFERROR(INDEX('Hashtag Bank'!$E$5:$E$104,MATCH(L25,'Hashtag Bank'!$B$5:$B$104,0)),"")) -> 3 | O25: Idea | P25: Video editor | Q25: =IF(A25&H25="","",TRIM(IF(AND(A25<>"",A25<TODAY(),O25<>"Published",O25<>"Repurpose"),"⚠ Overdue ","")&IF(AND(J25<>"",D25<>"",IFERROR(J25>INDEX(Setup!$E$9:$E$18,MATCH(D25,Setup!$B$9:$B$18,0)),FALSE())),"✂ Caption too long ","")&IF(AND(M25<>"",D25<>"",IFERROR(M25>INDEX(Setup!$F$9:$F$18,MATCH(D25,Setup!$B$9:$B$18,0)),FALSE())),"# Too many tags",""))) | Z25: =IF(COUNT(U25:X25)=0,"",SUM(U25:X25)) | AA25: =IF(OR(Z25="",N(T25)=0),"",Z25/T25) | AC25: =IF(A25="","",A25+N(C25)+ROW()/10^7) -> 46315.583 | AD25: =IF(A25="","",TEXT(A25,"0")&"|"&COUNTIFS('Content Log'!$A$5:$A$504,A25,'Content Log'!$AC$5:$AC$504,"<="&AC25)) -> 46315|1 | AE25: =IF(A25="","",IFERROR(INDEX(Setup!$N$9:$N$14,MATCH(O25,Setup!$M$9:$M$14,0))&" ","")&IF(C25="","",TEXT(C25,"h:mm AM/PM")&" ")&D25&IF(H25="",""," · "&H25)) -> 💡 2:00 PM YouTube · Q4 content strategy masterclass | AF25: =IF(OR(A25="",AA25=""),"",IF(AND(A25>=Dashboard!$G$4,A25<=Dashboard!$I$4),AA25+ROW()/10^9,"")) | AG25: =IF(A25="","",WEEKDAY(A25,2)) -> 2
A26: 46317 | B26: =IF(A26="","",TEXT(A26,"ddd")) -> Thu | C26: 0.41666667 | D26: Pinterest | E26: Pin | F26: Educate | G26: Evergreen | H26: Hashtag cheat sheet | J26: =IF(I26="","",LEN(I26)) | K26: Save | L26: Pinterest – SEO | M26: =IF(L26="","",IFERROR(INDEX('Hashtag Bank'!$E$5:$E$104,MATCH(L26,'Hashtag Bank'!$B$5:$B$104,0)),"")) -> 3 | O26: Idea | P26: Designer | Q26: =IF(A26&H26="","",TRIM(IF(AND(A26<>"",A26<TODAY(),O26<>"Published",O26<>"Repurpose"),"⚠ Overdue ","")&IF(AND(J26<>"",D26<>"",IFERROR(J26>INDEX(Setup!$E$9:$E$18,MATCH(D26,Setup!$B$9:$B$18,0)),FALSE())),"✂ Caption too long ","")&IF(AND(M26<>"",D26<>"",IFERROR(M26>INDEX(Setup!$F$9:$F$18,MATCH(D26,Setup!$B$9:$B$18,0)),FALSE())),"# Too many tags",""))) | Z26: =IF(COUNT(U26:X26)=0,"",SUM(U26:X26)) | AA26: =IF(OR(Z26="",N(T26)=0),"",Z26/T26) | AC26: =IF(A26="","",A26+N(C26)+ROW()/10^7) -> 46317.417 | AD26: =IF(A26="","",TEXT(A26,"0")&"|"&COUNTIFS('Content Log'!$A$5:$A$504,A26,'Content Log'!$AC$5:$AC$504,"<="&AC26)) -> 46317|1 | AE26: =IF(A26="","",IFERROR(INDEX(Setup!$N$9:$N$14,MATCH(O26,Setup!$M$9:$M$14,0))&" ","")&IF(C26="","",TEXT(C26,"h:mm AM/PM")&" ")&D26&IF(H26="",""," · "&H26)) -> 💡 10:00 AM Pinterest · Hashtag cheat sheet | AF26: =IF(OR(A26="",AA26=""),"",IF(AND(A26>=Dashboard!$G$4,A26<=Dashboard!$I$4),AA26+ROW()/10^9,"")) | AG26: =IF(A26="","",WEEKDAY(A26,2)) -> 4
A27: 46322 | B27: =IF(A27="","",TEXT(A27,"ddd")) -> Tue | C27: 0.75 | D27: Instagram | E27: Carousel | F27: Community | H27: Your best fall content (UGC) | J27: =IF(I27="","",LEN(I27)) | K27: Tag us | L27: IG – Growth tips | M27: =IF(L27="","",IFERROR(INDEX('Hashtag Bank'!$E$5:$E$104,MATCH(L27,'Hashtag Bank'!$B$5:$B$104,0)),"")) -> 8 | O27: Idea | P27: VA | Q27: =IF(A27&H27="","",TRIM(IF(AND(A27<>"",A27<TODAY(),O27<>"Published",O27<>"Repurpose"),"⚠ Overdue ","")&IF(AND(J27<>"",D27<>"",IFERROR(J27>INDEX(Setup!$E$9:$E$18,MATCH(D27,Setup!$B$9:$B$18,0)),FALSE())),"✂ Caption too long ","")&IF(AND(M27<>"",D27<>"",IFERROR(M27>INDEX(Setup!$F$9:$F$18,MATCH(D27,Setup!$B$9:$B$18,0)),FALSE())),"# Too many tags",""))) | Z27: =IF(COUNT(U27:X27)=0,"",SUM(U27:X27)) | AA27: =IF(OR(Z27="",N(T27)=0),"",Z27/T27) | AC27: =IF(A27="","",A27+N(C27)+ROW()/10^7) -> 46322.75 | AD27: =IF(A27="","",TEXT(A27,"0")&"|"&COUNTIFS('Content Log'!$A$5:$A$504,A27,'Content Log'!$AC$5:$AC$504,"<="&AC27)) -> 46322|1 | AE27: =IF(A27="","",IFERROR(INDEX(Setup!$N$9:$N$14,MATCH(O27,Setup!$M$9:$M$14,0))&" ","")&IF(C27="","",TEXT(C27,"h:mm AM/PM")&" ")&D27&IF(H27="",""," · "&H27)) -> 💡 6:00 PM Instagram · Your best fall content (UGC) | AF27: =IF(OR(A27="",AA27=""),"",IF(AND(A27>=Dashboard!$G$4,A27<=Dashboard!$I$4),AA27+ROW()/10^9,"")) | AG27: =IF(A27="","",WEEKDAY(A27,2)) -> 2
A28: 46325 | B28: =IF(A28="","",TEXT(A28,"ddd")) -> Fri | C28: 0.70833333 | D28: TikTok | E28: Reel / Short video | F28: Entertain | G28: Halloween | H28: Spooky planner tour | J28: =IF(I28="","",LEN(I28)) | K28: Follow | L28: TikTok – Trends | M28: =IF(L28="","",IFERROR(INDEX('Hashtag Bank'!$E$5:$E$104,MATCH(L28,'Hashtag Bank'!$B$5:$B$104,0)),"")) -> 4 | O28: Idea | P28: Video editor | Q28: =IF(A28&H28="","",TRIM(IF(AND(A28<>"",A28<TODAY(),O28<>"Published",O28<>"Repurpose"),"⚠ Overdue ","")&IF(AND(J28<>"",D28<>"",IFERROR(J28>INDEX(Setup!$E$9:$E$18,MATCH(D28,Setup!$B$9:$B$18,0)),FALSE())),"✂ Caption too long ","")&IF(AND(M28<>"",D28<>"",IFERROR(M28>INDEX(Setup!$F$9:$F$18,MATCH(D28,Setup!$B$9:$B$18,0)),FALSE())),"# Too many tags",""))) | Z28: =IF(COUNT(U28:X28)=0,"",SUM(U28:X28)) | AA28: =IF(OR(Z28="",N(T28)=0),"",Z28/T28) | AC28: =IF(A28="","",A28+N(C28)+ROW()/10^7) -> 46325.708 | AD28: =IF(A28="","",TEXT(A28,"0")&"|"&COUNTIFS('Content Log'!$A$5:$A$504,A28,'Content Log'!$AC$5:$AC$504,"<="&AC28)) -> 46325|1 | AE28: =IF(A28="","",IFERROR(INDEX(Setup!$N$9:$N$14,MATCH(O28,Setup!$M$9:$M$14,0))&" ","")&IF(C28="","",TEXT(C28,"h:mm AM/PM")&" ")&D28&IF(H28="",""," · "&H28)) -> 💡 5:00 PM TikTok · Spooky planner tour | AF28: =IF(OR(A28="",AA28=""),"",IF(AND(A28>=Dashboard!$G$4,A28<=Dashboard!$I$4),AA28+ROW()/10^9,"")) | AG28: =IF(A28="","",WEEKDAY(A28,2)) -> 5
B29: =IF(A29="","",TEXT(A29,"ddd")) | J29: =IF(I29="","",LEN(I29)) | M29: =IF(L29="","",IFERROR(INDEX('Hashtag Bank'!$E$5:$E$104,MATCH(L29,'Hashtag Bank'!$B$5:$B$104,0)),"")) | Q29: =IF(A29&H29="","",TRIM(IF(AND(A29<>"",A29<TODAY(),O29<>"Published",O29<>"Repurpose"),"⚠ Overdue ","")&IF(AND(J29<>"",D29<>"",IFERROR(J29>INDEX(Setup!$E$9:$E$18,MATCH(D29,Setup!$B$9:$B$18,0)),FALSE())),"✂ Caption too long ","")&IF(AND(M29<>"",D29<>"",IFERROR(M29>INDEX(Setup!$F$9:$F$18,MATCH(D29,Setup!$B$9:$B$18,0)),FALSE())),"# Too many tags",""))) | Z29: =IF(COUNT(U29:X29)=0,"",SUM(U29:X29)) | AA29: =IF(OR(Z29="",N(T29)=0),"",Z29/T29) | AC29: =IF(A29="","",A29+N(C29)+ROW()/10^7) | AD29: =IF(A29="","",TEXT(A29,"0")&"|"&COUNTIFS('Content Log'!$A$5:$A$504,A29,'Content Log'!$AC$5:$AC$504,"<="&AC29)) | AE29: =IF(A29="","",IFERROR(INDEX(Setup!$N$9:$N$14,MATCH(O29,Setup!$M$9:$M$14,0))&" ","")&IF(C29="","",TEXT(C29,"h:mm AM/PM")&" ")&D29&IF(H29="",""," · "&H29)) | AF29: =IF(OR(A29="",AA29=""),"",IF(AND(A29>=Dashboard!$G$4,A29<=Dashboard!$I$4),AA29+ROW()/10^9,"")) | AG29: =IF(A29="","",WEEKDAY(A29,2))
B30: =IF(A30="","",TEXT(A30,"ddd")) | J30: =IF(I30="","",LEN(I30)) | M30: =IF(L30="","",IFERROR(INDEX('Hashtag Bank'!$E$5:$E$104,MATCH(L30,'Hashtag Bank'!$B$5:$B$104,0)),"")) | Q30: =IF(A30&H30="","",TRIM(IF(AND(A30<>"",A30<TODAY(),O30<>"Published",O30<>"Repurpose"),"⚠ Overdue ","")&IF(AND(J30<>"",D30<>"",IFERROR(J30>INDEX(Setup!$E$9:$E$18,MATCH(D30,Setup!$B$9:$B$18,0)),FALSE())),"✂ Caption too long ","")&IF(AND(M30<>"",D30<>"",IFERROR(M30>INDEX(Setup!$F$9:$F$18,MATCH(D30,Setup!$B$9:$B$18,0)),FALSE())),"# Too many tags",""))) | Z30: =IF(COUNT(U30:X30)=0,"",SUM(U30:X30)) | AA30: =IF(OR(Z30="",N(T30)=0),"",Z30/T30) | AC30: =IF(A30="","",A30+N(C30)+ROW()/10^7) | AD30: =IF(A30="","",TEXT(A30,"0")&"|"&COUNTIFS('Content Log'!$A$5:$A$504,A30,'Content Log'!$AC$5:$AC$504,"<="&AC30)) | AE30: =IF(A30="","",IFERROR(INDEX(Setup!$N$9:$N$14,MATCH(O30,Setup!$M$9:$M$14,0))&" ","")&IF(C30="","",TEXT(C30,"h:mm AM/PM")&" ")&D30&IF(H30="",""," · "&H30)) | AF30: =IF(OR(A30="",AA30=""),"",IF(AND(A30>=Dashboard!$G$4,A30<=Dashboard!$I$4),AA30+ROW()/10^9,"")) | AG30: =IF(A30="","",WEEKDAY(A30,2))
B31: =IF(A31="","",TEXT(A31,"ddd")) | J31: =IF(I31="","",LEN(I31)) | M31: =IF(L31="","",IFERROR(INDEX('Hashtag Bank'!$E$5:$E$104,MATCH(L31,'Hashtag Bank'!$B$5:$B$104,0)),"")) | Q31: =IF(A31&H31="","",TRIM(IF(AND(A31<>"",A31<TODAY(),O31<>"Published",O31<>"Repurpose"),"⚠ Overdue ","")&IF(AND(J31<>"",D31<>"",IFERROR(J31>INDEX(Setup!$E$9:$E$18,MATCH(D31,Setup!$B$9:$B$18,0)),FALSE())),"✂ Caption too long ","")&IF(AND(M31<>"",D31<>"",IFERROR(M31>INDEX(Setup!$F$9:$F$18,MATCH(D31,Setup!$B$9:$B$18,0)),FALSE())),"# Too many tags",""))) | Z31: =IF(COUNT(U31:X31)=0,"",SUM(U31:X31)) | AA31: =IF(OR(Z31="",N(T31)=0),"",Z31/T31) | AC31: =IF(A31="","",A31+N(C31)+ROW()/10^7) | AD31: =IF(A31="","",TEXT(A31,"0")&"|"&COUNTIFS('Content Log'!$A$5:$A$504,A31,'Content Log'!$AC$5:$AC$504,"<="&AC31)) | AE31: =IF(A31="","",IFERROR(INDEX(Setup!$N$9:$N$14,MATCH(O31,Setup!$M$9:$M$14,0))&" ","")&IF(C31="","",TEXT(C31,"h:mm AM/PM")&" ")&D31&IF(H31="",""," · "&H31)) | AF31: =IF(OR(A31="",AA31=""),"",IF(AND(A31>=Dashboard!$G$4,A31<=Dashboard!$I$4),AA31+ROW()/10^9,"")) | AG31: =IF(A31="","",WEEKDAY(A31,2))
B32: =IF(A32="","",TEXT(A32,"ddd")) | J32: =IF(I32="","",LEN(I32)) | M32: =IF(L32="","",IFERROR(INDEX('Hashtag Bank'!$E$5:$E$104,MATCH(L32,'Hashtag Bank'!$B$5:$B$104,0)),"")) | Q32: =IF(A32&H32="","",TRIM(IF(AND(A32<>"",A32<TODAY(),O32<>"Published",O32<>"Repurpose"),"⚠ Overdue ","")&IF(AND(J32<>"",D32<>"",IFERROR(J32>INDEX(Setup!$E$9:$E$18,MATCH(D32,Setup!$B$9:$B$18,0)),FALSE())),"✂ Caption too long ","")&IF(AND(M32<>"",D32<>"",IFERROR(M32>INDEX(Setup!$F$9:$F$18,MATCH(D32,Setup!$B$9:$B$18,0)),FALSE())),"# Too many tags",""))) | Z32: =IF(COUNT(U32:X32)=0,"",SUM(U32:X32)) | AA32: =IF(OR(Z32="",N(T32)=0),"",Z32/T32) | AC32: =IF(A32="","",A32+N(C32)+ROW()/10^7) | AD32: =IF(A32="","",TEXT(A32,"0")&"|"&COUNTIFS('Content Log'!$A$5:$A$504,A32,'Content Log'!$AC$5:$AC$504,"<="&AC32)) | AE32: =IF(A32="","",IFERROR(INDEX(Setup!$N$9:$N$14,MATCH(O32,Setup!$M$9:$M$14,0))&" ","")&IF(C32="","",TEXT(C32,"h:mm AM/PM")&" ")&D32&IF(H32="",""," · "&H32)) | AF32: =IF(OR(A32="",AA32=""),"",IF(AND(A32>=Dashboard!$G$4,A32<=Dashboard!$I$4),AA32+ROW()/10^9,"")) | AG32: =IF(A32="","",WEEKDAY(A32,2))
B33: =IF(A33="","",TEXT(A33,"ddd")) | J33: =IF(I33="","",LEN(I33)) | M33: =IF(L33="","",IFERROR(INDEX('Hashtag Bank'!$E$5:$E$104,MATCH(L33,'Hashtag Bank'!$B$5:$B$104,0)),"")) | Q33: =IF(A33&H33="","",TRIM(IF(AND(A33<>"",A33<TODAY(),O33<>"Published",O33<>"Repurpose"),"⚠ Overdue ","")&IF(AND(J33<>"",D33<>"",IFERROR(J33>INDEX(Setup!$E$9:$E$18,MATCH(D33,Setup!$B$9:$B$18,0)),FALSE())),"✂ Caption too long ","")&IF(AND(M33<>"",D33<>"",IFERROR(M33>INDEX(Setup!$F$9:$F$18,MATCH(D33,Setup!$B$9:$B$18,0)),FALSE())),"# Too many tags",""))) | Z33: =IF(COUNT(U33:X33)=0,"",SUM(U33:X33)) | AA33: =IF(OR(Z33="",N(T33)=0),"",Z33/T33) | AC33: =IF(A33="","",A33+N(C33)+ROW()/10^7) | AD33: =IF(A33="","",TEXT(A33,"0")&"|"&COUNTIFS('Content Log'!$A$5:$A$504,A33,'Content Log'!$AC$5:$AC$504,"<="&AC33)) | AE33: =IF(A33="","",IFERROR(INDEX(Setup!$N$9:$N$14,MATCH(O33,Setup!$M$9:$M$14,0))&" ","")&IF(C33="","",TEXT(C33,"h:mm AM/PM")&" ")&D33&IF(H33="",""," · "&H33)) | AF33: =IF(OR(A33="",AA33=""),"",IF(AND(A33>=Dashboard!$G$4,A33<=Dashboard!$I$4),AA33+ROW()/10^9,"")) | AG33: =IF(A33="","",WEEKDAY(A33,2))
B34: =IF(A34="","",TEXT(A34,"ddd")) | J34: =IF(I34="","",LEN(I34)) | M34: =IF(L34="","",IFERROR(INDEX('Hashtag Bank'!$E$5:$E$104,MATCH(L34,'Hashtag Bank'!$B$5:$B$104,0)),"")) | Q34: =IF(A34&H34="","",TRIM(IF(AND(A34<>"",A34<TODAY(),O34<>"Published",O34<>"Repurpose"),"⚠ Overdue ","")&IF(AND(J34<>"",D34<>"",IFERROR(J34>INDEX(Setup!$E$9:$E$18,MATCH(D34,Setup!$B$9:$B$18,0)),FALSE())),"✂ Caption too long ","")&IF(AND(M34<>"",D34<>"",IFERROR(M34>INDEX(Setup!$F$9:$F$18,MATCH(D34,Setup!$B$9:$B$18,0)),FALSE())),"# Too many tags",""))) | Z34: =IF(COUNT(U34:X34)=0,"",SUM(U34:X34)) | AA34: =IF(OR(Z34="",N(T34)=0),"",Z34/T34) | AC34: =IF(A34="","",A34+N(C34)+ROW()/10^7) | AD34: =IF(A34="","",TEXT(A34,"0")&"|"&COUNTIFS('Content Log'!$A$5:$A$504,A34,'Content Log'!$AC$5:$AC$504,"<="&AC34)) | AE34: =IF(A34="","",IFERROR(INDEX(Setup!$N$9:$N$14,MATCH(O34,Setup!$M$9:$M$14,0))&" ","")&IF(C34="","",TEXT(C34,"h:mm AM/PM")&" ")&D34&IF(H34="",""," · "&H34)) | AF34: =IF(OR(A34="",AA34=""),"",IF(AND(A34>=Dashboard!$G$4,A34<=Dashboard!$I$4),AA34+ROW()/10^9,"")) | AG34: =IF(A34="","",WEEKDAY(A34,2))
B35: =IF(A35="","",TEXT(A35,"ddd")) | J35: =IF(I35="","",LEN(I35)) | M35: =IF(L35="","",IFERROR(INDEX('Hashtag Bank'!$E$5:$E$104,MATCH(L35,'Hashtag Bank'!$B$5:$B$104,0)),"")) | Q35: =IF(A35&H35="","",TRIM(IF(AND(A35<>"",A35<TODAY(),O35<>"Published",O35<>"Repurpose"),"⚠ Overdue ","")&IF(AND(J35<>"",D35<>"",IFERROR(J35>INDEX(Setup!$E$9:$E$18,MATCH(D35,Setup!$B$9:$B$18,0)),FALSE())),"✂ Caption too long ","")&IF(AND(M35<>"",D35<>"",IFERROR(M35>INDEX(Setup!$F$9:$F$18,MATCH(D35,Setup!$B$9:$B$18,0)),FALSE())),"# Too many tags",""))) | Z35: =IF(COUNT(U35:X35)=0,"",SUM(U35:X35)) | AA35: =IF(OR(Z35="",N(T35)=0),"",Z35/T35) | AC35: =IF(A35="","",A35+N(C35)+ROW()/10^7) | AD35: =IF(A35="","",TEXT(A35,"0")&"|"&COUNTIFS('Content Log'!$A$5:$A$504,A35,'Content Log'!$AC$5:$AC$504,"<="&AC35)) | AE35: =IF(A35="","",IFERROR(INDEX(Setup!$N$9:$N$14,MATCH(O35,Setup!$M$9:$M$14,0))&" ","")&IF(C35="","",TEXT(C35,"h:mm AM/PM")&" ")&D35&IF(H35="",""," · "&H35)) | AF35: =IF(OR(A35="",AA35=""),"",IF(AND(A35>=Dashboard!$G$4,A35<=Dashboard!$I$4),AA35+ROW()/10^9,"")) | AG35: =IF(A35="","",WEEKDAY(A35,2))
B36: =IF(A36="","",TEXT(A36,"ddd")) | J36: =IF(I36="","",LEN(I36)) | M36: =IF(L36="","",IFERROR(INDEX('Hashtag Bank'!$E$5:$E$104,MATCH(L36,'Hashtag Bank'!$B$5:$B$104,0)),"")) | Q36: =IF(A36&H36="","",TRIM(IF(AND(A36<>"",A36<TODAY(),O36<>"Published",O36<>"Repurpose"),"⚠ Overdue ","")&IF(AND(J36<>"",D36<>"",IFERROR(J36>INDEX(Setup!$E$9:$E$18,MATCH(D36,Setup!$B$9:$B$18,0)),FALSE())),"✂ Caption too long ","")&IF(AND(M36<>"",D36<>"",IFERROR(M36>INDEX(Setup!$F$9:$F$18,MATCH(D36,Setup!$B$9:$B$18,0)),FALSE())),"# Too many tags",""))) | Z36: =IF(COUNT(U36:X36)=0,"",SUM(U36:X36)) | AA36: =IF(OR(Z36="",N(T36)=0),"",Z36/T36) | AC36: =IF(A36="","",A36+N(C36)+ROW()/10^7) | AD36: =IF(A36="","",TEXT(A36,"0")&"|"&COUNTIFS('Content Log'!$A$5:$A$504,A36,'Content Log'!$AC$5:$AC$504,"<="&AC36)) | AE36: =IF(A36="","",IFERROR(INDEX(Setup!$N$9:$N$14,MATCH(O36,Setup!$M$9:$M$14,0))&" ","")&IF(C36="","",TEXT(C36,"h:mm AM/PM")&" ")&D36&IF(H36="",""," · "&H36)) | AF36: =IF(OR(A36="",AA36=""),"",IF(AND(A36>=Dashboard!$G$4,A36<=Dashboard!$I$4),AA36+ROW()/10^9,"")) | AG36: =IF(A36="","",WEEKDAY(A36,2))
B37: =IF(A37="","",TEXT(A37,"ddd")) | J37: =IF(I37="","",LEN(I37)) | M37: =IF(L37="","",IFERROR(INDEX('Hashtag Bank'!$E$5:$E$104,MATCH(L37,'Hashtag Bank'!$B$5:$B$104,0)),"")) | Q37: =IF(A37&H37="","",TRIM(IF(AND(A37<>"",A37<TODAY(),O37<>"Published",O37<>"Repurpose"),"⚠ Overdue ","")&IF(AND(J37<>"",D37<>"",IFERROR(J37>INDEX(Setup!$E$9:$E$18,MATCH(D37,Setup!$B$9:$B$18,0)),FALSE())),"✂ Caption too long ","")&IF(AND(M37<>"",D37<>"",IFERROR(M37>INDEX(Setup!$F$9:$F$18,MATCH(D37,Setup!$B$9:$B$18,0)),FALSE())),"# Too many tags",""))) | Z37: =IF(COUNT(U37:X37)=0,"",SUM(U37:X37)) | AA37: =IF(OR(Z37="",N(T37)=0),"",Z37/T37) | AC37: =IF(A37="","",A37+N(C37)+ROW()/10^7) | AD37: =IF(A37="","",TEXT(A37,"0")&"|"&COUNTIFS('Content Log'!$A$5:$A$504,A37,'Content Log'!$AC$5:$AC$504,"<="&AC37)) | AE37: =IF(A37="","",IFERROR(INDEX(Setup!$N$9:$N$14,MATCH(O37,Setup!$M$9:$M$14,0))&" ","")&IF(C37="","",TEXT(C37,"h:mm AM/PM")&" ")&D37&IF(H37="",""," · "&H37)) | AF37: =IF(OR(A37="",AA37=""),"",IF(AND(A37>=Dashboard!$G$4,A37<=Dashboard!$I$4),AA37+ROW()/10^9,"")) | AG37: =IF(A37="","",WEEKDAY(A37,2))
B38: =IF(A38="","",TEXT(A38,"ddd")) | J38: =IF(I38="","",LEN(I38)) | M38: =IF(L38="","",IFERROR(INDEX('Hashtag Bank'!$E$5:$E$104,MATCH(L38,'Hashtag Bank'!$B$5:$B$104,0)),"")) | Q38: =IF(A38&H38="","",TRIM(IF(AND(A38<>"",A38<TODAY(),O38<>"Published",O38<>"Repurpose"),"⚠ Overdue ","")&IF(AND(J38<>"",D38<>"",IFERROR(J38>INDEX(Setup!$E$9:$E$18,MATCH(D38,Setup!$B$9:$B$18,0)),FALSE())),"✂ Caption too long ","")&IF(AND(M38<>"",D38<>"",IFERROR(M38>INDEX(Setup!$F$9:$F$18,MATCH(D38,Setup!$B$9:$B$18,0)),FALSE())),"# Too many tags",""))) | Z38: =IF(COUNT(U38:X38)=0,"",SUM(U38:X38)) | AA38: =IF(OR(Z38="",N(T38)=0),"",Z38/T38) | AC38: =IF(A38="","",A38+N(C38)+ROW()/10^7) | AD38: =IF(A38="","",TEXT(A38,"0")&"|"&COUNTIFS('Content Log'!$A$5:$A$504,A38,'Content Log'!$AC$5:$AC$504,"<="&AC38)) | AE38: =IF(A38="","",IFERROR(INDEX(Setup!$N$9:$N$14,MATCH(O38,Setup!$M$9:$M$14,0))&" ","")&IF(C38="","",TEXT(C38,"h:mm AM/PM")&" ")&D38&IF(H38="",""," · "&H38)) | AF38: =IF(OR(A38="",AA38=""),"",IF(AND(A38>=Dashboard!$G$4,A38<=Dashboard!$I$4),AA38+ROW()/10^9,"")) | AG38: =IF(A38="","",WEEKDAY(A38,2))
B39: =IF(A39="","",TEXT(A39,"ddd")) | J39: =IF(I39="","",LEN(I39)) | M39: =IF(L39="","",IFERROR(INDEX('Hashtag Bank'!$E$5:$E$104,MATCH(L39,'Hashtag Bank'!$B$5:$B$104,0)),"")) | Q39: =IF(A39&H39="","",TRIM(IF(AND(A39<>"",A39<TODAY(),O39<>"Published",O39<>"Repurpose"),"⚠ Overdue ","")&IF(AND(J39<>"",D39<>"",IFERROR(J39>INDEX(Setup!$E$9:$E$18,MATCH(D39,Setup!$B$9:$B$18,0)),FALSE())),"✂ Caption too long ","")&IF(AND(M39<>"",D39<>"",IFERROR(M39>INDEX(Setup!$F$9:$F$18,MATCH(D39,Setup!$B$9:$B$18,0)),FALSE())),"# Too many tags",""))) | Z39: =IF(COUNT(U39:X39)=0,"",SUM(U39:X39)) | AA39: =IF(OR(Z39="",N(T39)=0),"",Z39/T39) | AC39: =IF(A39="","",A39+N(C39)+ROW()/10^7) | AD39: =IF(A39="","",TEXT(A39,"0")&"|"&COUNTIFS('Content Log'!$A$5:$A$504,A39,'Content Log'!$AC$5:$AC$504,"<="&AC39)) | AE39: =IF(A39="","",IFERROR(INDEX(Setup!$N$9:$N$14,MATCH(O39,Setup!$M$9:$M$14,0))&" ","")&IF(C39="","",TEXT(C39,"h:mm AM/PM")&" ")&D39&IF(H39="",""," · "&H39)) | AF39: =IF(OR(A39="",AA39=""),"",IF(AND(A39>=Dashboard!$G$4,A39<=Dashboard!$I$4),AA39+ROW()/10^9,"")) | AG39: =IF(A39="","",WEEKDAY(A39,2))
B40: =IF(A40="","",TEXT(A40,"ddd")) | J40: =IF(I40="","",LEN(I40)) | M40: =IF(L40="","",IFERROR(INDEX('Hashtag Bank'!$E$5:$E$104,MATCH(L40,'Hashtag Bank'!$B$5:$B$104,0)),"")) | Q40: =IF(A40&H40="","",TRIM(IF(AND(A40<>"",A40<TODAY(),O40<>"Published",O40<>"Repurpose"),"⚠ Overdue ","")&IF(AND(J40<>"",D40<>"",IFERROR(J40>INDEX(Setup!$E$9:$E$18,MATCH(D40,Setup!$B$9:$B$18,0)),FALSE())),"✂ Caption too long ","")&IF(AND(M40<>"",D40<>"",IFERROR(M40>INDEX(Setup!$F$9:$F$18,MATCH(D40,Setup!$B$9:$B$18,0)),FALSE())),"# Too many tags",""))) | Z40: =IF(COUNT(U40:X40)=0,"",SUM(U40:X40)) | AA40: =IF(OR(Z40="",N(T40)=0),"",Z40/T40) | AC40: =IF(A40="","",A40+N(C40)+ROW()/10^7) | AD40: =IF(A40="","",TEXT(A40,"0")&"|"&COUNTIFS('Content Log'!$A$5:$A$504,A40,'Content Log'!$AC$5:$AC$504,"<="&AC40)) | AE40: =IF(A40="","",IFERROR(INDEX(Setup!$N$9:$N$14,MATCH(O40,Setup!$M$9:$M$14,0))&" ","")&IF(C40="","",TEXT(C40,"h:mm AM/PM")&" ")&D40&IF(H40="",""," · "&H40)) | AF40: =IF(OR(A40="",AA40=""),"",IF(AND(A40>=Dashboard!$G$4,A40<=Dashboard!$I$4),AA40+ROW()/10^9,"")) | AG40: =IF(A40="","",WEEKDAY(A40,2))
...

Sheet Monthly Calendar
B1: 🗓️ Monthly Calendar
B2: Pick a month and year — the grid fills itself from the Content Log (first 3 posts per day, ordered by time).
B4: Month | C4: October | D4: Year | E4: 2026 | J4: month # | K4: =MATCH(C4,Setup!$R$9:$R$20,0) -> 10
B5: ="📅 "&COUNTIFS('Content Log'!$A$5:$A$504,">="&$K$5,'Content Log'!$A$5:$A$504,"<="&$K$7)&" posts planned ✅ "&COUNTIFS('Content Log'!$A$5:$A$504,">="&$K$5,'Content Log'!$A$5:$A$504,"<="&$K$7,'Content Log'!$O$5:$O$504,"Published")&" published 🕒 "&COUNTIFS('Content Log'!$A$5:$A$504,">="&$K$5,'Content Log'!$A$5:$A$504,"<="&$K$7,'Content Log'!$O$5:$O$504,"Scheduled")&" scheduled ⚠ "&COUNTIFS('Content Log'!$A$5:$A$504,">="&$K$5,'Content Log'!$A$5:$A$504,"<="&$K$7,'Content Log'!$A$5:$A$504,"<"&TODAY(),'Content Log'!$O$5:$O$504,"<>Published",'Content Log'!$O$5:$O$504,"<>Repurpose")&" overdue" -> 📅 20 posts planned ✅ 4 published 🕒 5 scheduled ⚠ 1 overdue | J5: 1st of month | K5: =DATE(E4,K4,1) -> 46296
J6: grid start | K6: =K5-MOD(WEEKDAY(K5)-IF(Setup!$C$5="Monday",2,1),7) -> 46292
B7: =TEXT($K$6+0,"dddd") -> Sunday | C7: =TEXT($K$6+1,"dddd") -> Monday | D7: =TEXT($K$6+2,"dddd") -> Tuesday | E7: =TEXT($K$6+3,"dddd") -> Wednesday | F7: =TEXT($K$6+4,"dddd") -> Thursday | G7: =TEXT($K$6+5,"dddd") -> Friday | H7: =TEXT($K$6+6,"dddd") -> Saturday | J7: month end | K7: =EOMONTH(K5,0) -> 46326
B8: =$K$6+0 -> 46292 | C8: =$K$6+1 -> 46293 | D8: =$K$6+2 -> 46294 | E8: =$K$6+3 -> 46295 | F8: =$K$6+4 -> 46296 | G8: =$K$6+5 -> 46297 | H8: =$K$6+6 -> 46298
B9: =IFERROR(INDEX('Content Log'!$AE$5:$AE$504,MATCH(TEXT(B$8,"0")&"|1",'Content Log'!$AD$5:$AD$504,0)),"") | C9: =IFERROR(INDEX('Content Log'!$AE$5:$AE$504,MATCH(TEXT(C$8,"0")&"|1",'Content Log'!$AD$5:$AD$504,0)),"") | D9: =IFERROR(INDEX('Content Log'!$AE$5:$AE$504,MATCH(TEXT(D$8,"0")&"|1",'Content Log'!$AD$5:$AD$504,0)),"") -> ✅ 10:00 AM Pinterest · Content calendar template | E9: =IFERROR(INDEX('Content Log'!$AE$5:$AE$504,MATCH(TEXT(E$8,"0")&"|1",'Content Log'!$AD$5:$AD$504,0)),"") | F9: =IFERROR(INDEX('Content Log'!$AE$5:$AE$504,MATCH(TEXT(F$8,"0")&"|1",'Content Log'!$AD$5:$AD$504,0)),"") -> ✅ 9:00 AM Instagram · Sneak peek: something new | G9: =IFERROR(INDEX('Content Log'!$AE$5:$AE$504,MATCH(TEXT(G$8,"0")&"|1",'Content Log'!$AD$5:$AD$504,0)),"") -> ✏️ 11:00 AM Facebook · Customer spotlight: Maya | H9: =IFERROR(INDEX('Content Log'!$AE$5:$AE$504,MATCH(TEXT(H$8,"0")&"|1",'Content Log'!$AD$5:$AD$504,0)),"") -> ✅ 2:00 PM YouTube · How I batch 30 posts in a day
B10: =IFERROR(INDEX('Content Log'!$AE$5:$AE$504,MATCH(TEXT(B$8,"0")&"|2",'Content Log'!$AD$5:$AD$504,0)),"") | C10: =IFERROR(INDEX('Content Log'!$AE$5:$AE$504,MATCH(TEXT(C$8,"0")&"|2",'Content Log'!$AD$5:$AD$504,0)),"") | D10: =IFERROR(INDEX('Content Log'!$AE$5:$AE$504,MATCH(TEXT(D$8,"0")&"|2",'Content Log'!$AD$5:$AD$504,0)),"") | E10: =IFERROR(INDEX('Content Log'!$AE$5:$AE$504,MATCH(TEXT(E$8,"0")&"|2",'Content Log'!$AD$5:$AD$504,0)),"") | F10: =IFERROR(INDEX('Content Log'!$AE$5:$AE$504,MATCH(TEXT(F$8,"0")&"|2",'Content Log'!$AD$5:$AD$504,0)),"") -> ✅ 5:00 PM Threads · Ask me anything Friday | G10: =IFERROR(INDEX('Content Log'!$AE$5:$AE$504,MATCH(TEXT(G$8,"0")&"|2",'Content Log'!$AD$5:$AD$504,0)),"") | H10: =IFERROR(INDEX('Content Log'!$AE$5:$AE$504,MATCH(TEXT(H$8,"0")&"|2",'Content Log'!$AD$5:$AD$504,0)),"") -> ✅ 7:00 PM TikTok · Trend: 'tell me without telling me'
B11: =IFERROR(INDEX('Content Log'!$AE$5:$AE$504,MATCH(TEXT(B$8,"0")&"|3",'Content Log'!$AD$5:$AD$504,0)),"") | C11: =IFERROR(INDEX('Content Log'!$AE$5:$AE$504,MATCH(TEXT(C$8,"0")&"|3",'Content Log'!$AD$5:$AD$504,0)),"") | D11: =IFERROR(INDEX('Content Log'!$AE$5:$AE$504,MATCH(TEXT(D$8,"0")&"|3",'Content Log'!$AD$5:$AD$504,0)),"") | E11: =IFERROR(INDEX('Content Log'!$AE$5:$AE$504,MATCH(TEXT(E$8,"0")&"|3",'Content Log'!$AD$5:$AD$504,0)),"") | F11: =IFERROR(INDEX('Content Log'!$AE$5:$AE$504,MATCH(TEXT(F$8,"0")&"|3",'Content Log'!$AD$5:$AD$504,0)),"") | G11: =IFERROR(INDEX('Content Log'!$AE$5:$AE$504,MATCH(TEXT(G$8,"0")&"|3",'Content Log'!$AD$5:$AD$504,0)),"") | H11: =IFERROR(INDEX('Content Log'!$AE$5:$AE$504,MATCH(TEXT(H$8,"0")&"|3",'Content Log'!$AD$5:$AD$504,0)),"")
B12: =IF(COUNTIF('Content Log'!$A$5:$A$504,B8)>3,"+"&(COUNTIF('Content Log'!$A$5:$A$504,B8)-3)&" more → see Weekly View","") | C12: =IF(COUNTIF('Content Log'!$A$5:$A$504,C8)>3,"+"&(COUNTIF('Content Log'!$A$5:$A$504,C8)-3)&" more → see Weekly View","") | D12: =IF(COUNTIF('Content Log'!$A$5:$A$504,D8)>3,"+"&(COUNTIF('Content Log'!$A$5:$A$504,D8)-3)&" more → see Weekly View","") | E12: =IF(COUNTIF('Content Log'!$A$5:$A$504,E8)>3,"+"&(COUNTIF('Content Log'!$A$5:$A$504,E8)-3)&" more → see Weekly View","") | F12: =IF(COUNTIF('Content Log'!$A$5:$A$504,F8)>3,"+"&(COUNTIF('Content Log'!$A$5:$A$504,F8)-3)&" more → see Weekly View","") | G12: =IF(COUNTIF('Content Log'!$A$5:$A$504,G8)>3,"+"&(COUNTIF('Content Log'!$A$5:$A$504,G8)-3)&" more → see Weekly View","") | H12: =IF(COUNTIF('Content Log'!$A$5:$A$504,H8)>3,"+"&(COUNTIF('Content Log'!$A$5:$A$504,H8)-3)&" more → see Weekly View","")
B13: =$K$6+7 -> 46299 | C13: =$K$6+8 -> 46300 | D13: =$K$6+9 -> 46301 | E13: =$K$6+10 -> 46302 | F13: =$K$6+11 -> 46303 | G13: =$K$6+12 -> 46304 | H13: =$K$6+13 -> 46305
B14: =IFERROR(INDEX('Content Log'!$AE$5:$AE$504,MATCH(TEXT(B$13,"0")&"|1",'Content Log'!$AD$5:$AD$504,0)),"") | C14: =IFERROR(INDEX('Content Log'!$AE$5:$AE$504,MATCH(TEXT(C$13,"0")&"|1",'Content Log'!$AD$5:$AD$504,0)),"") -> 🕒 9:00 AM Instagram · Poll: which colourway? | D14: =IFERROR(INDEX('Content Log'!$AE$5:$AE$504,MATCH(TEXT(D$13,"0")&"|1",'Content Log'!$AD$5:$AD$504,0)),"") -> 🕒 12:00 PM LinkedIn · The 4-pillar content framework | E14: =IFERROR(INDEX('Content Log'!$AE$5:$AE$504,MATCH(TEXT(E$13,"0")&"|1",'Content Log'!$AD$5:$AD$504,0)),"") -> 👀 6:30 PM X / Twitter · Thread: my posting workflow | F14: =IFERROR(INDEX('Content Log'!$AE$5:$AE$504,MATCH(TEXT(F$13,"0")&"|1",'Content Log'!$AD$5:$AD$504,0)),"") -> 🕒 10:00 AM Pinterest · Cozy fall desk setup | G14: =IFERROR(INDEX('Content Log'!$AE$5:$AE$504,MATCH(TEXT(G$13,"0")&"|1",'Content Log'!$AD$5:$AD$504,0)),"") -> ✏️ 5:00 PM Instagram · Day in the life of a planner shop | H14: =IFERROR(INDEX('Content Log'!$AE$5:$AE$504,MATCH(TEXT(H$13,"0")&"|1",'Content Log'!$AD$5:$AD$504,0)),"")
B15: =IFERROR(INDEX('Content Log'!$AE$5:$AE$504,MATCH(TEXT(B$13,"0")&"|2",'Content Log'!$AD$5:$AD$504,0)),"") | C15: =IFERROR(INDEX('Content Log'!$AE$5:$AE$504,MATCH(TEXT(C$13,"0")&"|2",'Content Log'!$AD$5:$AD$504,0)),"") | D15: =IFERROR(INDEX('Content Log'!$AE$5:$AE$504,MATCH(TEXT(D$13,"0")&"|2",'Content Log'!$AD$5:$AD$504,0)),"") | E15: =IFERROR(INDEX('Content Log'!$AE$5:$AE$504,MATCH(TEXT(E$13,"0")&"|2",'Content Log'!$AD$5:$AD$504,0)),"") | F15: =IFERROR(INDEX('Content Log'!$AE$5:$AE$504,MATCH(TEXT(F$13,"0")&"|2",'Content Log'!$AD$5:$AD$504,0)),"") | G15: =IFERROR(INDEX('Content Log'!$AE$5:$AE$504,MATCH(TEXT(G$13,"0")&"|2",'Content Log'!$AD$5:$AD$504,0)),"") | H15: =IFERROR(INDEX('Content Log'!$AE$5:$AE$504,MATCH(TEXT(H$13,"0")&"|2",'Content Log'!$AD$5:$AD$504,0)),"")
